'use strict';
const test = require('tape-catch');

function promise_fulfills(t, expectedValue, promise, msg) {
  promise.then(value => {
    t.equal(value, expectedValue, msg);
  }, reason => {
    t.fail(msg + ': Rejected unexpectedly with: ' + reason);
  });
}

test('abort() on a released writer rejects', t => {
  const ws = new WritableStream({});

  const writer = ws.getWriter();
  writer.releaseLock();

  const abortPromise = writer.abort();
  abortPromise.then(() => {
    t.fail('abortPromise fulfilled unexpectedly');
    t.end();
  },
  r => {
    t.equal(r.constructor, TypeError, 'abort() should reject with a TypeError');
    t.end();
  });
});

test('Aborting a WritableStream immediately prevents future writes', t => {
  const ws = new WritableStream({
    write() {
      t.fail('Unexpected write() call');
      t.end();
    }
  });

  setTimeout(() => {
    const writer = ws.getWriter();

    writer.abort();
    writer.write(1);
    writer.write(2);

    setTimeout(() => {
      t.end();
    }, 100);
  }, 0);
});

test('Aborting a WritableStream prevents further writes after any that are in progress', t => {
  t.plan(2);

  let writeCount = 0;

  const ws = new WritableStream({
    write(chunk) {
      ++writeCount;

      if (writeCount > 1) {
        t.fail('Only the single in-progress chunk gets written to the sink');
        t.end();
        return;
      }

      t.equals(chunk, 1, 'chunk should be 1');

      return new Promise(resolve => setTimeout(resolve, 50));
    }
  });

  setTimeout(() => {
    const writer = ws.getWriter();

    writer.write(1);
    writer.write(2);
    writer.write(3);
    writer.abort();
    writer.write(4);
    writer.write(5);

    setTimeout(function () {
      t.pass('Passed 200 ms');
    }, 200);
  }, 0);
});

test('Fulfillment value of ws.abort() call must be undefined even if the underlying sink returns a non-undefined value',
     t => {
  const ws = new WritableStream({
    abort() {
      return 'Hello';
    }
  });

  const writer = ws.getWriter();

  const abortPromise = writer.abort('a');
  abortPromise.then(value => {
    t.equal(value, undefined, 'fulfillment value must be undefined');
    t.end();
  }).catch(() => {
    t.fail('abortPromise is rejected');
    t.end();
  });
});

test('WritableStream if sink\'s abort throws, the promise returned by writer.abort() rejects', t => {
  const errorInSinkAbort = new Error('Sorry, it just wasn\'t meant to be.');
  const ws = new WritableStream({
    abort() {
      throw errorInSinkAbort;
    }
  });

  const writer = ws.getWriter();

  const abortPromise = writer.abort(undefined);
  abortPromise.then(
    () => {
      t.fail('abortPromise is fulfilled unexpectedly');
      t.end();
    },
    r => {
      t.equal(r, errorInSinkAbort, 'rejection reason of abortPromise must be errorInSinkAbort');
      t.end();
    }
  );
});

test('WritableStream if sink\'s abort throws, the promise returned by ws.abort() rejects', t => {
  const errorInSinkAbort = new Error('Sorry, it just wasn\'t meant to be.');
  const ws = new WritableStream({
    abort() {
      throw errorInSinkAbort;
    }
  });

  const abortPromise = ws.abort(undefined);
  abortPromise.then(
    () => {
      t.fail('abortPromise is fulfilled unexpectedly');
      t.end();
    },
    r => {
      t.equal(r, errorInSinkAbort, 'rejection reason of abortPromise must be errorInSinkAbort');
      t.end();
    }
  );
});

test('Aborting a WritableStream passes through the given reason', t => {
  let recordedReason;
  const ws = new WritableStream({
    abort(reason) {
      recordedReason = reason;
    }
  });

  const writer = ws.getWriter();

  const passedReason = new Error('Sorry, it just wasn\'t meant to be.');
  writer.abort(passedReason);

  t.equal(recordedReason, passedReason);
  t.end();
});

test('Aborting a WritableStream puts it in an errored state, with stored error equal to the abort reason', t => {
  t.plan(4);

  let recordedReason;
  const ws = new WritableStream();

  const writer = ws.getWriter();

  const passedReason = new Error('Sorry, it just wasn\'t meant to be.');
  writer.abort(passedReason);

  writer.write().then(
    () => t.fail('writing should not succeed'),
    r => t.equal(r.constructor, TypeError, 'writing should reject with the given reason')
  );

  writer.close().then(
    () => t.fail('closing should not succeed'),
    r => t.equal(r.constructor, TypeError, 'closing should reject with the given reason')
  );

  writer.abort().then(
    () => t.fail('aborting a second time should not succeed'),
    r => t.equal(r.constructor, TypeError, 'aborting a second time should reject with the given reason')
  );

  writer.closed.then(
    () => t.fail('closed fulfilled unexpectedly'),
    r => t.equal(r.constructor, TypeError, 'closed should reject with a TypeError')
  );
});

test('Aborting a WritableStream causes any outstanding ready promises to be fulfilled immediately', t => {
  let recordedReason;
  const ws = new WritableStream({
    write(chunk) {
      return new Promise(() => { }); // forever-pending, so normally .ready would not fulfill.
    }
  });

  const writer = ws.getWriter();

  writer.write('a');

  writer.ready.then(() => {
    t.end();
  });

  const passedReason = new Error('Sorry, it just wasn\'t meant to be.');
  writer.abort(passedReason);
});

test('Aborting a WritableStream causes any outstanding write() promises to be rejected with the abort reason', t => {
  t.plan(1);

  const ws = new WritableStream();

  const writer = ws.getWriter();

  writer.write('a').then(
    () => t.fail('writing should not succeed'),
    r => t.equal(r.constructor, TypeError, 'writing should reject with a TypeError')
  );

  const passedReason = new Error('Sorry, it just wasn\'t meant to be.');
  writer.abort(passedReason);
});

test('Closing but then immediately aborting a WritableStream causes the stream to error', t => {
  t.plan(1);

  const ws = new WritableStream();

  const writer = ws.getWriter();

  writer.close();

  const passedReason = new Error('Sorry, it just wasn\'t meant to be.');
  writer.abort(passedReason);

  writer.closed.then(
    () => t.fail('the stream should not close successfully'),
    r => t.equal(r.constructor, TypeError, 'the stream should be errored with a TypeError')
  );
});

test('Closing a WritableStream and aborting it while it closes causes the stream to error', t => {
  const ws = new WritableStream({
    close() {
      return new Promise(() => { }); // forever-pending
    }
  });

  const writer = ws.getWriter();

  writer.close();

  const passedReason = new Error('Sorry, it just wasn\'t meant to be.');

  setTimeout(() => {
    writer.abort(passedReason);
  }, 20);

  writer.closed.then(
    () => t.fail('the stream should not close successfully'),
    r => {
      t.equal(r.constructor, TypeError, 'the stream should be errored with a TypeError');
      t.end();
    }
  );
});

test('Aborting a WritableStream after it is closed is a no-op', t => {
  t.plan(2);

  const ws = new WritableStream();

  const writer = ws.getWriter();

  writer.close();

  setTimeout(() => {
    writer.abort().then(
      v => t.equal(v, undefined, 'abort promise should fulfill with undefined'),
      t.error
    );

    promise_fulfills(t, undefined, writer.closed, 'closed should still be fulfilled');
  }, 0);
});

test('WritableStream should call underlying sink\'s close if no abort is supplied', t => {
  const ws = new WritableStream({
    close() {
      t.equal(arguments.length, 0, 'close() was called (with no arguments)');
      t.end();
    }
  });

  const writer = ws.getWriter();

  writer.abort();
});
